Workbook

Sheet Dim Customers
A1: Customer ID | B1: Customer Name | C1: City | D1: State | E1: Pincode | F1: EmailID | G1: Phone Number
A2: 1 | B2: Aarav Singh | C2: Nagpur | D2: Maharashtra | E2: 440001 | F2: 1Aarav@gmail.com | G2: 860135097
A3: 2 | B3: Aditi Patel | C3: Bhopal | D3: Madhya Pradesh | E3: 462001 | F3: 2Aditi@gmail.com | G3: 896750475
A4: 3 | B4: Aman Verma | C4: Ahmedabad | D4: Gujarat | E4: 380001 | F4: 3Aman@gmail.com | G4: 833807373
A5: 4 | B5: Ananya Mehta | C5: Bhopal | D5: Madhya Pradesh | E5: 462001 | F5: 4Ananya@gmail.com | G5: 804038105
A6: 5 | B6: Aniket Sharma | C6: Indore | D6: Madhya Pradesh | E6: 452001 | F6: 5Aniket@gmail.com | G6: 986307349
A7: 6 | B7: Anjali Rao | C7: Bhopal | D7: Madhya Pradesh | E7: 462001 | F7: 6Anjali@gmail.com | G7: 963288063
A8: 7 | B8: Arjun Joshi | C8: Kanpur | D8: Uttar Pradesh | E8: 208001 | F8: 7Arjun@gmail.com | G8: 988368456
A9: 8 | B9: Aryan Gupta | C9: Mumbai | D9: Maharashtra | E9: 400001 | F9: 8Aryan@gmail.com | G9: 953821775
A10: 9 | B10: Avni Iyer | C10: Kanpur | D10: Uttar Pradesh | E10: 208001 | F10: 9Avni@gmail.com | G10: 863732487
A11: 10 | B11: Dhruv Desai | C11: Pune | D11: Maharashtra | E11: 411001 | F11: 10Dhruv@gmail.com | G11: 900051106
A12: 11 | B12: Diya Kapoor | C12: Mumbai | D12: Maharashtra | E12: 400001 | F12: 11Diya@gmail.com | G12: 845767347
A13: 12 | B13: Gaurav Nair | C13: Pune | D13: Maharashtra | E13: 411001 | F13: 12Gaurav@gmail.com | G13: 882241217
... A51: 50 | B51: Yash Malhotra | C51: Lucknow | D51: Uttar Pradesh | E51: 226001 | F51: 50Yash@gmail.com | G51: 910695779

Sheet Dim Product
A1: ProductID | B1: Product Name | C1: Product Line | D1: Price (INR)
A2: P001 | B2: Apple iPhone 14 | C2: Electronics | D2: 79999
A3: P002 | B3: Samsung Galaxy S21 | C3: Electronics | D3: 69999
A4: P003 | B4: Sony Bravia 55" TV | C4: Electronics | D4: 89999
A5: P004 | B5: HP Pavilion Laptop | C5: Electronics | D5: 64999
A6: P005 | B6: Apple MacBook Air | C6: Electronics | D6: 92499
A7: P006 | B7: Nike Running Shoes | C7: Footwear | D7: 7499
A8: P007 | B8: Adidas Sneakers | C8: Footwear | D8: 6999
A9: P008 | B9: Puma Sports Shoes | C9: Footwear | D9: 5499
A10: P009 | B10: Levi's Denim Jeans | C10: Clothing | D10: 3499
A11: P010 | B11: Zara Casual Shirt | C11: Clothing | D11: 2199
A12: P011 | B12: H&M T-Shirt | C12: Clothing | D12: 1499
A13: P012 | B13: FabIndia Kurta | C13: Clothing | D13: 2999
... A31: P030 | B31: Nivea Body Lotion | C31: Personal Care | D31: 399

Sheet Dim Promotion 
A1: PromotionID | B1: Promotion Name | C1: Ad Type | D1: Coupon Code | E1: Price Reduction Type
A2: PR001 | B2: Summer Sale | C2: Email | D2: SUMMER21 | E2: 20% off
A3: PR002 | B3: Festive Diwali | C3: Social Media | D3: FESTIVE2022 | E3: 10% off
A4: PR003 | B4: New Year Special | C4: Website Banner | D4: NEWYEAR22 | E4: Buy 1 Get 1 Free
A5: PR004 | B5: Weekend Flash Sale | C5: Mobile Push | D5: FLASH50 | E5: 50% off
A6: PR005 | B6: Clearance Sale | C6: In-App | D6: CLEARANCE23 | E6: 70% off

Sheet Sheet3
A1: Date (dd/mm/yyyy) | B1: CustomerID | C1: PromotionID | D1: Product ID | E1: Units Sold | F1: Price Per Unit | G1: Total Sales | H1: Discount Percentage | I1: Discount Value | J1: Net Sales
A2: 43865 | B2: 10 | C2: 0 | D2: P004 | E2: 2 | F2: =E2*'Dim Product'!D2 -> 159998 | G2: =E2*F2 -> 319996
A3: 44700 | B3: 28 | C3: PR001 | D3: P027 | E3: 3 | F3: =E3*'Dim Product'!D3 -> 209997 | G3: =E3*F3 -> 629991
A4: 44743 | B4: 2 | C4: 0 | D4: P011 | E4: 3 | F4: =E4*'Dim Product'!D4 -> 269997 | G4: =E4*F4 -> 809991
A5: 44657 | B5: 11 | C5: PR001 | D5: P009 | E5: 2 | F5: =E5*'Dim Product'!D5 -> 129998 | G5: =E5*F5 -> 259996
A6: 44563 | B6: 34 | C6: 0 | D6: P002 | E6: 1 | F6: =E6*'Dim Product'!D6 -> 92499 | G6: =E6*F6 -> 92499
A7: 44968 | B7: 44 | C7: 0 | D7: P019 | E7: 1 | F7: =E7*'Dim Product'!D7 -> 7499 | G7: =E7*F7 -> 7499
A8: 45122 | B8: 42 | C8: PR004 | D8: P014 | E8: 2 | F8: =E8*'Dim Product'!D8 -> 13998 | G8: =E8*F8 -> 27996
A9: 44224 | B9: 46 | C9: 0 | D9: P025 | E9: 1 | F9: =E9*'Dim Product'!D9 -> 5499 | G9: =E9*F9 -> 5499
A10: 44706 | B10: 21 | C10: PR001 | D10: P019 | E10: 2 | F10: =E10*'Dim Product'!D10 -> 6998 | G10: =E10*F10 -> 13996
A11: 45071 | B11: 48 | C11: PR001 | D11: P005 | E11: 3 | F11: =E11*'Dim Product'!D11 -> 6597 | G11: =E11*F11 -> 19791
A12: 45202 | B12: 18 | C12: 0 | D12: P001 | E12: 1 | F12: =E12*'Dim Product'!D12 -> 1499 | G12: =E12*F12 -> 1499
A13: 44066 | B13: 28 | C13: 0 | D13: P010 | E13: 2 | F13: =E13*'Dim Product'!D13 -> 5998 | G13: =E13*F13 -> 11996
A14: 45075 | B14: 17 | C14: PR001 | D14: P002 | E14: 3 | F14: =E14*'Dim Product'!D14 -> 47997 | G14: =E14*F14 -> 143991
A15: 45115 | B15: 28 | C15: PR004 | D15: P002 | E15: 3 | F15: =E15*'Dim Product'!D15 -> 14997 | G15: =E15*F15 -> 44991
A16: 44908 | B16: 23 | C16: 0 | D16: P002 | E16: 3 | F16: =E16*'Dim Product'!D16 -> 25497 | G16: =E16*F16 -> 76491
A17: 44147 | B17: 8 | C17: 0 | D17: P029 | E17: 1 | F17: =E17*'Dim Product'!D17 -> 24999 | G17: =E17*F17 -> 24999
A18: 44910 | B18: 41 | C18: 0 | D18: P022 | E18: 3 | F18: =E18*'Dim Product'!D18 -> 31497 | G18: =E18*F18 -> 94491
A19: 44562 | B19: 48 | C19: PR003 | D19: P011 | E19: 3 | F19: =E19*'Dim Product'!D19 -> 6897 | G19: =E19*F19 -> 20691
A20: 44105 | B20: 12 | C20: 0 | D20: P010 | E20: 1 | F20: =E20*'Dim Product'!D20 -> 5999 | G20: =E20*F20 -> 5999
A21: 44508 | B21: 40 | C21: 0 | D21: P012 | E21: 1 | F21: =E21*'Dim Product'!D21 -> 12999 | G21: =E21*F21 -> 12999
A22: 44001 | B22: 31 | C22: 0 | D22: P016 | E22: 3 | F22: =E22*'Dim Product'!D22 -> 3897 | G22: =E22*F22 -> 11691
A23: 44399 | B23: 6 | C23: 0 | D23: P023 | E23: 3 | F23: =E23*'Dim Product'!D23 -> 5997 | G23: =E23*F23 -> 17991
A24: 44959 | B24: 25 | C24: 0 | D24: P029 | E24: 2 | F24: =E24*'Dim Product'!D24 -> 2998 | G24: =E24*F24 -> 5996
A25: 44599 | B25: 27 | C25: 0 | D25: P028 | E25: 2 | F25: =E25*'Dim Product'!D25 -> 5598 | G25: =E25*F25 -> 11196
A26: 43919 | B26: 31 | C26: 0 | D26: P008 | E26: 2 | F26: =E26*'Dim Product'!D26 -> 17998 | G26: =E26*F26 -> 35996
A27: 44247 | B27: 40 | C27: 0 | D27: P013 | E27: 1 | F27: =E27*'Dim Product'!D27 -> 5499 | G27: =E27*F27 -> 5499
A28: 43947 | B28: 3 | C28: PR001 | D28: P005 | E28: 3 | F28: =E28*'Dim Product'!D28 -> 2097 | G28: =E28*F28 -> 6291
A29: 44931 | B29: 44 | C29: 0 | D29: P016 | E29: 2 | F29: =E29*'Dim Product'!D29 -> 698 | G29: =E29*F29 -> 1396
A30: 44630 | B30: 2 | C30: 0 | D30: P010 | E30: 3 | F30: =E30*'Dim Product'!D30 -> 297 | G30: =E30*F30 -> 891
A31: 44304 | B31: 17 | C31: PR001 | D31: P017 | E31: 1 | F31: =E31*'Dim Product'!D31 -> 399 | G31: =E31*F31 -> 399
A32: 43860 | B32: 1 | C32: 0 | D32: P018 | E32: 1 | F32: =E32*'Dim Product'!D32 -> 0 | G32: =E32*F32 -> 0
A33: 44332 | B33: 43 | C33: PR001 | D33: P001 | E33: 3 | F33: =E33*'Dim Product'!D33 -> 0 | G33: =E33*F33 -> 0
A34: 43881 | B34: 24 | C34: 0 | D34: P020 | E34: 2 | F34: =E34*'Dim Product'!D34 -> 0 | G34: =E34*F34 -> 0
A35: 44071 | B35: 14 | C35: 0 | D35: P017 | E35: 3 | F35: =E35*'Dim Product'!D35 -> 0 | G35: =E35*F35 -> 0
A36: 44616 | B36: 20 | C36: 0 | D36: P013 | E36: 3 | F36: =E36*'Dim Product'!D36 -> 0 | G36: =E36*F36 -> 0
A37: 44092 | B37: 14 | C37: 0 | D37: P025 | E37: 2 | F37: =E37*'Dim Product'!D37 -> 0 | G37: =E37*F37 -> 0
A38: 44016 | B38: 49 | C38: PR004 | D38: P023 | E38: 1 | F38: =E38*'Dim Product'!D38 -> 0 | G38: =E38*F38 -> 0
A39: 44357 | B39: 31 | C39: 0 | D39: P014 | E39: 1 | F39: =E39*'Dim Product'!D39 -> 0 | G39: =E39*F39 -> 0
A40: 45291 | B40: 29 | C40: PR005 | D40: P018 | E40: 1 | F40: =E40*'Dim Product'!D40 -> 0 | G40: =E40*F40 -> 0
...
